2023-07-12 07:24:52,008 - werkzeug - INFO - [31m[1mWARNING: This is a development server. Do not use it in a production deployment. Use a production WSGI server instead.[0m
 * Running on all addresses (0.0.0.0)
 * Running on http://127.0.0.1:80
 * Running on http://172.31.196.56:80
2023-07-12 07:24:52,009 - werkzeug - INFO - [33mPress CTRL+C to quit[0m
2023-07-12 07:24:53,939 - werkzeug - INFO - 172.31.196.1 - - [12/Jul/2023 07:24:53] "GET / HTTP/1.1" 200 -
2023-07-12 07:25:14,923 - werkzeug - INFO - 172.31.196.1 - - [12/Jul/2023 07:25:14] "GET / HTTP/1.1" 200 -
2023-07-12 15:40:02,955 - root - WARNING - Error in callback Monobank - 0
2023-07-12 15:40:06,516 - root - WARNING - Error in callback Monobank - 0
2023-07-12 15:40:55,251 - root - WARNING - Error in callback Monobank - 0
2023-07-12 15:41:46,194 - root - INFO - Command from user was started
2023-07-12 15:41:57,887 - root - INFO - Command from user was started
2023-07-12 15:42:51,141 - root - WARNING - Command from group was started
2023-07-12 15:43:20,654 - root - WARNING - Command from group was started
2023-07-12 19:07:04,313 - root - WARNING - SQL coonnection failure
2023-07-12 19:22:55,590 - root - WARNING - SQL coonnection failure
2023-07-12 19:22:55,593 - root - WARNING - SQL coonnection failure
2023-07-12 19:22:56,024 - TeleBot - ERROR - Threaded polling exception: A request to the Telegram API was unsuccessful. Error code: 409. Description: Conflict: terminated by other getUpdates request; make sure that only one bot instance is running
2023-07-12 19:22:56,025 - TeleBot - ERROR - Exception traceback:
Traceback (most recent call last):
  File "/home/neo_ubuntu/git_repo/venv/lib/python3.11/site-packages/telebot/__init__.py", line 1073, in __threaded_polling
    polling_thread.raise_exceptions()
  File "/home/neo_ubuntu/git_repo/venv/lib/python3.11/site-packages/telebot/util.py", line 108, in raise_exceptions
    raise self.exception_info
  File "/home/neo_ubuntu/git_repo/venv/lib/python3.11/site-packages/telebot/util.py", line 90, in run
    task(*args, **kwargs)
  File "/home/neo_ubuntu/git_repo/venv/lib/python3.11/site-packages/telebot/__init__.py", line 649, in __retrieve_updates
    updates = self.get_updates(offset=(self.last_update_id + 1),
             ^^^^^^^^^^^^^^^^^^^^^^^^^^^^^^^^^^^^^^^^^^^^^^^^^^^
  File "/home/neo_ubuntu/git_repo/venv/lib/python3.11/site-packages/telebot/__init__.py", line 623, in get_updates
    json_updates = apihelper.get_updates(self.token, offset, limit, timeout, allowed_updates, long_polling_timeout)
                   ^^^^^^^^^^^^^^^^^^^^^^^^^^^^^^^^^^^^^^^^^^^^^^^^^^^^^^^^^^^^^^^^^^^^^^^^^^^^^^^^^^^^^^^^^^^^^^^^
  File "/home/neo_ubuntu/git_repo/venv/lib/python3.11/site-packages/telebot/apihelper.py", line 321, in get_updates
    return _make_request(token, method_url, params=payload)
           ^^^^^^^^^^^^^^^^^^^^^^^^^^^^^^^^^^^^^^^^^^^^^^^^
  File "/home/neo_ubuntu/git_repo/venv/lib/python3.11/site-packages/telebot/apihelper.py", line 162, in _make_request
    json_result = _check_result(method_name, result)
                  ^^^^^^^^^^^^^^^^^^^^^^^^^^^^^^^^^^
  File "/home/neo_ubuntu/git_repo/venv/lib/python3.11/site-packages/telebot/apihelper.py", line 189, in _check_result
    raise ApiTelegramException(method_name, result, result_json)
telebot.apihelper.ApiTelegramException: A request to the Telegram API was unsuccessful. Error code: 409. Description: Conflict: terminated by other getUpdates request; make sure that only one bot instance is running

2023-07-12 19:22:59,805 - TeleBot - ERROR - Threaded polling exception: A request to the Telegram API was unsuccessful. Error code: 409. Description: Conflict: terminated by other getUpdates request; make sure that only one bot instance is running
2023-07-12 19:22:59,806 - TeleBot - ERROR - Exception traceback:
Traceback (most recent call last):
  File "/home/neo_ubuntu/git_repo/venv/lib/python3.11/site-packages/telebot/__init__.py", line 1073, in __threaded_polling
    polling_thread.raise_exceptions()
  File "/home/neo_ubuntu/git_repo/venv/lib/python3.11/site-packages/telebot/util.py", line 108, in raise_exceptions
    raise self.exception_info
  File "/home/neo_ubuntu/git_repo/venv/lib/python3.11/site-packages/telebot/util.py", line 90, in run
    task(*args, **kwargs)
  File "/home/neo_ubuntu/git_repo/venv/lib/python3.11/site-packages/telebot/__init__.py", line 649, in __retrieve_updates
    updates = self.get_updates(offset=(self.last_update_id + 1),
             ^^^^^^^^^^^^^^^^^^^^^^^^^^^^^^^^^^^^^^^^^^^^^^^^^^^
  File "/home/neo_ubuntu/git_repo/venv/lib/python3.11/site-packages/telebot/__init__.py", line 623, in get_updates
    json_updates = apihelper.get_updates(self.token, offset, limit, timeout, allowed_updates, long_polling_timeout)
                   ^^^^^^^^^^^^^^^^^^^^^^^^^^^^^^^^^^^^^^^^^^^^^^^^^^^^^^^^^^^^^^^^^^^^^^^^^^^^^^^^^^^^^^^^^^^^^^^^
  File "/home/neo_ubuntu/git_repo/venv/lib/python3.11/site-packages/telebot/apihelper.py", line 321, in get_updates
    return _make_request(token, method_url, params=payload)
           ^^^^^^^^^^^^^^^^^^^^^^^^^^^^^^^^^^^^^^^^^^^^^^^^
  File "/home/neo_ubuntu/git_repo/venv/lib/python3.11/site-packages/telebot/apihelper.py", line 162, in _make_request
    json_result = _check_result(method_name, result)
                  ^^^^^^^^^^^^^^^^^^^^^^^^^^^^^^^^^^
  File "/home/neo_ubuntu/git_repo/venv/lib/python3.11/site-packages/telebot/apihelper.py", line 189, in _check_result
    raise ApiTelegramException(method_name, result, result_json)
telebot.apihelper.ApiTelegramException: A request to the Telegram API was unsuccessful. Error code: 409. Description: Conflict: terminated by other getUpdates request; make sure that only one bot instance is running

2023-07-12 19:23:00,114 - TeleBot - ERROR - Threaded polling exception: A request to the Telegram API was unsuccessful. Error code: 409. Description: Conflict: terminated by other getUpdates request; make sure that only one bot instance is running
2023-07-12 19:23:00,115 - TeleBot - ERROR - Exception traceback:
Traceback (most recent call last):
  File "/home/neo_ubuntu/git_repo/venv/lib/python3.11/site-packages/telebot/__init__.py", line 1073, in __threaded_polling
    polling_thread.raise_exceptions()
  File "/home/neo_ubuntu/git_repo/venv/lib/python3.11/site-packages/telebot/util.py", line 108, in raise_exceptions
    raise self.exception_info
  File "/home/neo_ubuntu/git_repo/venv/lib/python3.11/site-packages/telebot/util.py", line 90, in run
    task(*args, **kwargs)
  File "/home/neo_ubuntu/git_repo/venv/lib/python3.11/site-packages/telebot/__init__.py", line 649, in __retrieve_updates
    updates = self.get_updates(offset=(self.last_update_id + 1),
             ^^^^^^^^^^^^^^^^^^^^^^^^^^^^^^^^^^^^^^^^^^^^^^^^^^^
  File "/home/neo_ubuntu/git_repo/venv/lib/python3.11/site-packages/telebot/__init__.py", line 623, in get_updates
    json_updates = apihelper.get_updates(self.token, offset, limit, timeout, allowed_updates, long_polling_timeout)
                   ^^^^^^^^^^^^^^^^^^^^^^^^^^^^^^^^^^^^^^^^^^^^^^^^^^^^^^^^^^^^^^^^^^^^^^^^^^^^^^^^^^^^^^^^^^^^^^^^
  File "/home/neo_ubuntu/git_repo/venv/lib/python3.11/site-packages/telebot/apihelper.py", line 321, in get_updates
    return _make_request(token, method_url, params=payload)
           ^^^^^^^^^^^^^^^^^^^^^^^^^^^^^^^^^^^^^^^^^^^^^^^^
  File "/home/neo_ubuntu/git_repo/venv/lib/python3.11/site-packages/telebot/apihelper.py", line 162, in _make_request
    json_result = _check_result(method_name, result)
                  ^^^^^^^^^^^^^^^^^^^^^^^^^^^^^^^^^^
  File "/home/neo_ubuntu/git_repo/venv/lib/python3.11/site-packages/telebot/apihelper.py", line 189, in _check_result
    raise ApiTelegramException(method_name, result, result_json)
telebot.apihelper.ApiTelegramException: A request to the Telegram API was unsuccessful. Error code: 409. Description: Conflict: terminated by other getUpdates request; make sure that only one bot instance is running

2023-07-12 19:23:03,679 - TeleBot - ERROR - Threaded polling exception: A request to the Telegram API was unsuccessful. Error code: 409. Description: Conflict: terminated by other getUpdates request; make sure that only one bot instance is running
2023-07-12 19:23:03,680 - TeleBot - ERROR - Exception traceback:
Traceback (most recent call last):
  File "/home/neo_ubuntu/git_repo/venv/lib/python3.11/site-packages/telebot/__init__.py", line 1073, in __threaded_polling
    polling_thread.raise_exceptions()
  File "/home/neo_ubuntu/git_repo/venv/lib/python3.11/site-packages/telebot/util.py", line 108, in raise_exceptions
    raise self.exception_info
  File "/home/neo_ubuntu/git_repo/venv/lib/python3.11/site-packages/telebot/util.py", line 90, in run
    task(*args, **kwargs)
  File "/home/neo_ubuntu/git_repo/venv/lib/python3.11/site-packages/telebot/__init__.py", line 649, in __retrieve_updates
    updates = self.get_updates(offset=(self.last_update_id + 1),
             ^^^^^^^^^^^^^^^^^^^^^^^^^^^^^^^^^^^^^^^^^^^^^^^^^^^
  File "/home/neo_ubuntu/git_repo/venv/lib/python3.11/site-packages/telebot/__init__.py", line 623, in get_updates
    json_updates = apihelper.get_updates(self.token, offset, limit, timeout, allowed_updates, long_polling_timeout)
                   ^^^^^^^^^^^^^^^^^^^^^^^^^^^^^^^^^^^^^^^^^^^^^^^^^^^^^^^^^^^^^^^^^^^^^^^^^^^^^^^^^^^^^^^^^^^^^^^^
  File "/home/neo_ubuntu/git_repo/venv/lib/python3.11/site-packages/telebot/apihelper.py", line 321, in get_updates
    return _make_request(token, method_url, params=payload)
           ^^^^^^^^^^^^^^^^^^^^^^^^^^^^^^^^^^^^^^^^^^^^^^^^
  File "/home/neo_ubuntu/git_repo/venv/lib/python3.11/site-packages/telebot/apihelper.py", line 162, in _make_request
    json_result = _check_result(method_name, result)
                  ^^^^^^^^^^^^^^^^^^^^^^^^^^^^^^^^^^
  File "/home/neo_ubuntu/git_repo/venv/lib/python3.11/site-packages/telebot/apihelper.py", line 189, in _check_result
    raise ApiTelegramException(method_name, result, result_json)
telebot.apihelper.ApiTelegramException: A request to the Telegram API was unsuccessful. Error code: 409. Description: Conflict: terminated by other getUpdates request; make sure that only one bot instance is running

2023-07-12 19:23:04,240 - TeleBot - ERROR - Threaded polling exception: A request to the Telegram API was unsuccessful. Error code: 409. Description: Conflict: terminated by other getUpdates request; make sure that only one bot instance is running
2023-07-12 19:23:04,241 - TeleBot - ERROR - Exception traceback:
Traceback (most recent call last):
  File "/home/neo_ubuntu/git_repo/venv/lib/python3.11/site-packages/telebot/__init__.py", line 1073, in __threaded_polling
    polling_thread.raise_exceptions()
  File "/home/neo_ubuntu/git_repo/venv/lib/python3.11/site-packages/telebot/util.py", line 108, in raise_exceptions
    raise self.exception_info
  File "/home/neo_ubuntu/git_repo/venv/lib/python3.11/site-packages/telebot/util.py", line 90, in run
    task(*args, **kwargs)
  File "/home/neo_ubuntu/git_repo/venv/lib/python3.11/site-packages/telebot/__init__.py", line 649, in __retrieve_updates
    updates = self.get_updates(offset=(self.last_update_id + 1),
             ^^^^^^^^^^^^^^^^^^^^^^^^^^^^^^^^^^^^^^^^^^^^^^^^^^^
  File "/home/neo_ubuntu/git_repo/venv/lib/python3.11/site-packages/telebot/__init__.py", line 623, in get_updates
    json_updates = apihelper.get_updates(self.token, offset, limit, timeout, allowed_updates, long_polling_timeout)
                   ^^^^^^^^^^^^^^^^^^^^^^^^^^^^^^^^^^^^^^^^^^^^^^^^^^^^^^^^^^^^^^^^^^^^^^^^^^^^^^^^^^^^^^^^^^^^^^^^
  File "/home/neo_ubuntu/git_repo/venv/lib/python3.11/site-packages/telebot/apihelper.py", line 321, in get_updates
    return _make_request(token, method_url, params=payload)
           ^^^^^^^^^^^^^^^^^^^^^^^^^^^^^^^^^^^^^^^^^^^^^^^^
  File "/home/neo_ubuntu/git_repo/venv/lib/python3.11/site-packages/telebot/apihelper.py", line 162, in _make_request
    json_result = _check_result(method_name, result)
                  ^^^^^^^^^^^^^^^^^^^^^^^^^^^^^^^^^^
  File "/home/neo_ubuntu/git_repo/venv/lib/python3.11/site-packages/telebot/apihelper.py", line 189, in _check_result
    raise ApiTelegramException(method_name, result, result_json)
telebot.apihelper.ApiTelegramException: A request to the Telegram API was unsuccessful. Error code: 409. Description: Conflict: terminated by other getUpdates request; make sure that only one bot instance is running

2023-07-12 19:23:10,973 - root - WARNING - SQL coonnection failure
2023-07-12 19:24:05,312 - root - WARNING - SQL coonnection failure
2023-07-12 19:24:34,820 - root - WARNING - SQL coonnection failure
2023-07-12 19:25:50,388 - root - WARNING - SQL coonnection failure
2023-07-12 19:28:18,228 - root - WARNING - SQL coonnection failure
2023-07-12 19:30:33,974 - root - WARNING - SQL coonnection failure
2023-07-12 19:31:34,663 - root - WARNING - SQL coonnection failure
2023-07-12 19:32:15,325 - root - WARNING - SQL coonnection failure
2023-07-12 19:35:49,765 - root - WARNING - SQL coonnection failure
2023-07-12 19:36:37,647 - root - WARNING - SQL coonnection failure
2023-07-12 19:37:14,598 - TeleBot - ERROR - Threaded polling exception: A request to the Telegram API was unsuccessful. Error code: 409. Description: Conflict: terminated by other getUpdates request; make sure that only one bot instance is running
2023-07-12 19:37:14,600 - TeleBot - ERROR - Exception traceback:
Traceback (most recent call last):
  File "/home/neo_ubuntu/git_repo/venv/lib/python3.11/site-packages/telebot/__init__.py", line 1073, in __threaded_polling
    polling_thread.raise_exceptions()
  File "/home/neo_ubuntu/git_repo/venv/lib/python3.11/site-packages/telebot/util.py", line 108, in raise_exceptions
    raise self.exception_info
  File "/home/neo_ubuntu/git_repo/venv/lib/python3.11/site-packages/telebot/util.py", line 90, in run
    task(*args, **kwargs)
  File "/home/neo_ubuntu/git_repo/venv/lib/python3.11/site-packages/telebot/__init__.py", line 649, in __retrieve_updates
    updates = self.get_updates(offset=(self.last_update_id + 1),
             ^^^^^^^^^^^^^^^^^^^^^^^^^^^^^^^^^^^^^^^^^^^^^^^^^^^
  File "/home/neo_ubuntu/git_repo/venv/lib/python3.11/site-packages/telebot/__init__.py", line 623, in get_updates
    json_updates = apihelper.get_updates(self.token, offset, limit, timeout, allowed_updates, long_polling_timeout)
                   ^^^^^^^^^^^^^^^^^^^^^^^^^^^^^^^^^^^^^^^^^^^^^^^^^^^^^^^^^^^^^^^^^^^^^^^^^^^^^^^^^^^^^^^^^^^^^^^^
  File "/home/neo_ubuntu/git_repo/venv/lib/python3.11/site-packages/telebot/apihelper.py", line 321, in get_updates
    return _make_request(token, method_url, params=payload)
           ^^^^^^^^^^^^^^^^^^^^^^^^^^^^^^^^^^^^^^^^^^^^^^^^
  File "/home/neo_ubuntu/git_repo/venv/lib/python3.11/site-packages/telebot/apihelper.py", line 162, in _make_request
    json_result = _check_result(method_name, result)
                  ^^^^^^^^^^^^^^^^^^^^^^^^^^^^^^^^^^
  File "/home/neo_ubuntu/git_repo/venv/lib/python3.11/site-packages/telebot/apihelper.py", line 189, in _check_result
    raise ApiTelegramException(method_name, result, result_json)
telebot.apihelper.ApiTelegramException: A request to the Telegram API was unsuccessful. Error code: 409. Description: Conflict: terminated by other getUpdates request; make sure that only one bot instance is running

2023-07-12 19:37:14,775 - root - WARNING - SQL coonnection failure
2023-07-12 19:37:14,915 - TeleBot - ERROR - Threaded polling exception: A request to the Telegram API was unsuccessful. Error code: 409. Description: Conflict: terminated by other getUpdates request; make sure that only one bot instance is running
2023-07-12 19:37:14,916 - TeleBot - ERROR - Exception traceback:
Traceback (most recent call last):
  File "/home/neo_ubuntu/git_repo/venv/lib/python3.11/site-packages/telebot/__init__.py", line 1073, in __threaded_polling
    polling_thread.raise_exceptions()
  File "/home/neo_ubuntu/git_repo/venv/lib/python3.11/site-packages/telebot/util.py", line 108, in raise_exceptions
    raise self.exception_info
  File "/home/neo_ubuntu/git_repo/venv/lib/python3.11/site-packages/telebot/util.py", line 90, in run
    task(*args, **kwargs)
  File "/home/neo_ubuntu/git_repo/venv/lib/python3.11/site-packages/telebot/__init__.py", line 649, in __retrieve_updates
    updates = self.get_updates(offset=(self.last_update_id + 1),
             ^^^^^^^^^^^^^^^^^^^^^^^^^^^^^^^^^^^^^^^^^^^^^^^^^^^
  File "/home/neo_ubuntu/git_repo/venv/lib/python3.11/site-packages/telebot/__init__.py", line 623, in get_updates
    json_updates = apihelper.get_updates(self.token, offset, limit, timeout, allowed_updates, long_polling_timeout)
                   ^^^^^^^^^^^^^^^^^^^^^^^^^^^^^^^^^^^^^^^^^^^^^^^^^^^^^^^^^^^^^^^^^^^^^^^^^^^^^^^^^^^^^^^^^^^^^^^^
  File "/home/neo_ubuntu/git_repo/venv/lib/python3.11/site-packages/telebot/apihelper.py", line 321, in get_updates
    return _make_request(token, method_url, params=payload)
           ^^^^^^^^^^^^^^^^^^^^^^^^^^^^^^^^^^^^^^^^^^^^^^^^
  File "/home/neo_ubuntu/git_repo/venv/lib/python3.11/site-packages/telebot/apihelper.py", line 162, in _make_request
    json_result = _check_result(method_name, result)
                  ^^^^^^^^^^^^^^^^^^^^^^^^^^^^^^^^^^
  File "/home/neo_ubuntu/git_repo/venv/lib/python3.11/site-packages/telebot/apihelper.py", line 189, in _check_result
    raise ApiTelegramException(method_name, result, result_json)
telebot.apihelper.ApiTelegramException: A request to the Telegram API was unsuccessful. Error code: 409. Description: Conflict: terminated by other getUpdates request; make sure that only one bot instance is running

2023-07-12 19:37:18,617 - TeleBot - ERROR - Threaded polling exception: A request to the Telegram API was unsuccessful. Error code: 409. Description: Conflict: terminated by other getUpdates request; make sure that only one bot instance is running
2023-07-12 19:37:18,618 - TeleBot - ERROR - Exception traceback:
Traceback (most recent call last):
  File "/home/neo_ubuntu/git_repo/venv/lib/python3.11/site-packages/telebot/__init__.py", line 1073, in __threaded_polling
    polling_thread.raise_exceptions()
  File "/home/neo_ubuntu/git_repo/venv/lib/python3.11/site-packages/telebot/util.py", line 108, in raise_exceptions
    raise self.exception_info
  File "/home/neo_ubuntu/git_repo/venv/lib/python3.11/site-packages/telebot/util.py", line 90, in run
    task(*args, **kwargs)
  File "/home/neo_ubuntu/git_repo/venv/lib/python3.11/site-packages/telebot/__init__.py", line 649, in __retrieve_updates
    updates = self.get_updates(offset=(self.last_update_id + 1),
             ^^^^^^^^^^^^^^^^^^^^^^^^^^^^^^^^^^^^^^^^^^^^^^^^^^^
  File "/home/neo_ubuntu/git_repo/venv/lib/python3.11/site-packages/telebot/__init__.py", line 623, in get_updates
    json_updates = apihelper.get_updates(self.token, offset, limit, timeout, allowed_updates, long_polling_timeout)
                   ^^^^^^^^^^^^^^^^^^^^^^^^^^^^^^^^^^^^^^^^^^^^^^^^^^^^^^^^^^^^^^^^^^^^^^^^^^^^^^^^^^^^^^^^^^^^^^^^
  File "/home/neo_ubuntu/git_repo/venv/lib/python3.11/site-packages/telebot/apihelper.py", line 321, in get_updates
    return _make_request(token, method_url, params=payload)
           ^^^^^^^^^^^^^^^^^^^^^^^^^^^^^^^^^^^^^^^^^^^^^^^^
  File "/home/neo_ubuntu/git_repo/venv/lib/python3.11/site-packages/telebot/apihelper.py", line 162, in _make_request
    json_result = _check_result(method_name, result)
                  ^^^^^^^^^^^^^^^^^^^^^^^^^^^^^^^^^^
  File "/home/neo_ubuntu/git_repo/venv/lib/python3.11/site-packages/telebot/apihelper.py", line 189, in _check_result
    raise ApiTelegramException(method_name, result, result_json)
telebot.apihelper.ApiTelegramException: A request to the Telegram API was unsuccessful. Error code: 409. Description: Conflict: terminated by other getUpdates request; make sure that only one bot instance is running

2023-07-12 19:37:19,180 - TeleBot - ERROR - Threaded polling exception: A request to the Telegram API was unsuccessful. Error code: 409. Description: Conflict: terminated by other getUpdates request; make sure that only one bot instance is running
2023-07-12 19:37:19,181 - TeleBot - ERROR - Exception traceback:
Traceback (most recent call last):
  File "/home/neo_ubuntu/git_repo/venv/lib/python3.11/site-packages/telebot/__init__.py", line 1073, in __threaded_polling
    polling_thread.raise_exceptions()
  File "/home/neo_ubuntu/git_repo/venv/lib/python3.11/site-packages/telebot/util.py", line 108, in raise_exceptions
    raise self.exception_info
  File "/home/neo_ubuntu/git_repo/venv/lib/python3.11/site-packages/telebot/util.py", line 90, in run
    task(*args, **kwargs)
  File "/home/neo_ubuntu/git_repo/venv/lib/python3.11/site-packages/telebot/__init__.py", line 649, in __retrieve_updates
    updates = self.get_updates(offset=(self.last_update_id + 1),
             ^^^^^^^^^^^^^^^^^^^^^^^^^^^^^^^^^^^^^^^^^^^^^^^^^^^
  File "/home/neo_ubuntu/git_repo/venv/lib/python3.11/site-packages/telebot/__init__.py", line 623, in get_updates
    json_updates = apihelper.get_updates(self.token, offset, limit, timeout, allowed_updates, long_polling_timeout)
                   ^^^^^^^^^^^^^^^^^^^^^^^^^^^^^^^^^^^^^^^^^^^^^^^^^^^^^^^^^^^^^^^^^^^^^^^^^^^^^^^^^^^^^^^^^^^^^^^^
  File "/home/neo_ubuntu/git_repo/venv/lib/python3.11/site-packages/telebot/apihelper.py", line 321, in get_updates
    return _make_request(token, method_url, params=payload)
           ^^^^^^^^^^^^^^^^^^^^^^^^^^^^^^^^^^^^^^^^^^^^^^^^
  File "/home/neo_ubuntu/git_repo/venv/lib/python3.11/site-packages/telebot/apihelper.py", line 162, in _make_request
    json_result = _check_result(method_name, result)
                  ^^^^^^^^^^^^^^^^^^^^^^^^^^^^^^^^^^
  File "/home/neo_ubuntu/git_repo/venv/lib/python3.11/site-packages/telebot/apihelper.py", line 189, in _check_result
    raise ApiTelegramException(method_name, result, result_json)
telebot.apihelper.ApiTelegramException: A request to the Telegram API was unsuccessful. Error code: 409. Description: Conflict: terminated by other getUpdates request; make sure that only one bot instance is running

2023-07-12 19:37:22,775 - TeleBot - ERROR - Threaded polling exception: A request to the Telegram API was unsuccessful. Error code: 409. Description: Conflict: terminated by other getUpdates request; make sure that only one bot instance is running
2023-07-12 19:37:22,776 - TeleBot - ERROR - Exception traceback:
Traceback (most recent call last):
  File "/home/neo_ubuntu/git_repo/venv/lib/python3.11/site-packages/telebot/__init__.py", line 1073, in __threaded_polling
    polling_thread.raise_exceptions()
  File "/home/neo_ubuntu/git_repo/venv/lib/python3.11/site-packages/telebot/util.py", line 108, in raise_exceptions
    raise self.exception_info
  File "/home/neo_ubuntu/git_repo/venv/lib/python3.11/site-packages/telebot/util.py", line 90, in run
    task(*args, **kwargs)
  File "/home/neo_ubuntu/git_repo/venv/lib/python3.11/site-packages/telebot/__init__.py", line 649, in __retrieve_updates
    updates = self.get_updates(offset=(self.last_update_id + 1),
             ^^^^^^^^^^^^^^^^^^^^^^^^^^^^^^^^^^^^^^^^^^^^^^^^^^^
  File "/home/neo_ubuntu/git_repo/venv/lib/python3.11/site-packages/telebot/__init__.py", line 623, in get_updates
    json_updates = apihelper.get_updates(self.token, offset, limit, timeout, allowed_updates, long_polling_timeout)
                   ^^^^^^^^^^^^^^^^^^^^^^^^^^^^^^^^^^^^^^^^^^^^^^^^^^^^^^^^^^^^^^^^^^^^^^^^^^^^^^^^^^^^^^^^^^^^^^^^
  File "/home/neo_ubuntu/git_repo/venv/lib/python3.11/site-packages/telebot/apihelper.py", line 321, in get_updates
    return _make_request(token, method_url, params=payload)
           ^^^^^^^^^^^^^^^^^^^^^^^^^^^^^^^^^^^^^^^^^^^^^^^^
  File "/home/neo_ubuntu/git_repo/venv/lib/python3.11/site-packages/telebot/apihelper.py", line 162, in _make_request
    json_result = _check_result(method_name, result)
                  ^^^^^^^^^^^^^^^^^^^^^^^^^^^^^^^^^^
  File "/home/neo_ubuntu/git_repo/venv/lib/python3.11/site-packages/telebot/apihelper.py", line 189, in _check_result
    raise ApiTelegramException(method_name, result, result_json)
telebot.apihelper.ApiTelegramException: A request to the Telegram API was unsuccessful. Error code: 409. Description: Conflict: terminated by other getUpdates request; make sure that only one bot instance is running

2023-07-12 19:37:23,840 - TeleBot - ERROR - Threaded polling exception: A request to the Telegram API was unsuccessful. Error code: 409. Description: Conflict: terminated by other getUpdates request; make sure that only one bot instance is running
2023-07-12 19:37:23,841 - TeleBot - ERROR - Exception traceback:
Traceback (most recent call last):
  File "/home/neo_ubuntu/git_repo/venv/lib/python3.11/site-packages/telebot/__init__.py", line 1073, in __threaded_polling
    polling_thread.raise_exceptions()
  File "/home/neo_ubuntu/git_repo/venv/lib/python3.11/site-packages/telebot/util.py", line 108, in raise_exceptions
    raise self.exception_info
  File "/home/neo_ubuntu/git_repo/venv/lib/python3.11/site-packages/telebot/util.py", line 90, in run
    task(*args, **kwargs)
  File "/home/neo_ubuntu/git_repo/venv/lib/python3.11/site-packages/telebot/__init__.py", line 649, in __retrieve_updates
    updates = self.get_updates(offset=(self.last_update_id + 1),
             ^^^^^^^^^^^^^^^^^^^^^^^^^^^^^^^^^^^^^^^^^^^^^^^^^^^
  File "/home/neo_ubuntu/git_repo/venv/lib/python3.11/site-packages/telebot/__init__.py", line 623, in get_updates
    json_updates = apihelper.get_updates(self.token, offset, limit, timeout, allowed_updates, long_polling_timeout)
                   ^^^^^^^^^^^^^^^^^^^^^^^^^^^^^^^^^^^^^^^^^^^^^^^^^^^^^^^^^^^^^^^^^^^^^^^^^^^^^^^^^^^^^^^^^^^^^^^^
  File "/home/neo_ubuntu/git_repo/venv/lib/python3.11/site-packages/telebot/apihelper.py", line 321, in get_updates
    return _make_request(token, method_url, params=payload)
           ^^^^^^^^^^^^^^^^^^^^^^^^^^^^^^^^^^^^^^^^^^^^^^^^
  File "/home/neo_ubuntu/git_repo/venv/lib/python3.11/site-packages/telebot/apihelper.py", line 162, in _make_request
    json_result = _check_result(method_name, result)
                  ^^^^^^^^^^^^^^^^^^^^^^^^^^^^^^^^^^
  File "/home/neo_ubuntu/git_repo/venv/lib/python3.11/site-packages/telebot/apihelper.py", line 189, in _check_result
    raise ApiTelegramException(method_name, result, result_json)
telebot.apihelper.ApiTelegramException: A request to the Telegram API was unsuccessful. Error code: 409. Description: Conflict: terminated by other getUpdates request; make sure that only one bot instance is running

2023-07-12 19:37:37,110 - root - WARNING - SQL coonnection failure
2023-07-12 19:39:02,103 - root - WARNING - SQL add to DB failure
2023-07-12 19:39:22,692 - root - WARNING - SQL add to DB failure
2023-07-12 19:41:32,292 - root - WARNING - ID 42568070
2023-07-12 19:41:32,292 - root - WARNING - ID mr_etelstan
2023-07-12 19:41:32,293 - root - WARNING - SQL add to DB failure
2023-07-12 19:44:30,674 - root - WARNING - ID 42568070
2023-07-12 19:44:30,674 - root - WARNING - ID mr_etelstan
2023-07-12 19:44:30,674 - root - WARNING - SQL add to DB failure
2023-07-12 19:45:49,941 - root - WARNING - ID 42568070
2023-07-12 19:45:49,941 - root - WARNING - ID mr_etelstan
2023-07-12 19:45:49,941 - root - WARNING - SQL add to DB failure
2023-07-12 19:49:14,154 - root - WARNING - ID 42568070
2023-07-12 19:49:14,154 - root - WARNING - ID mr_etelstan
2023-07-12 19:49:14,155 - root - WARNING - SQL add to DB failure
2023-07-12 19:50:46,359 - root - WARNING - ID 42568070
2023-07-12 19:50:46,359 - root - WARNING - ID mr_etelstan
2023-07-12 19:50:46,360 - root - WARNING - SQL add to DB failure
2023-07-12 19:51:18,496 - root - WARNING - ID 42568070
2023-07-12 19:51:18,496 - root - WARNING - ID mr_etelstan
2023-07-12 19:51:18,496 - root - WARNING - SQL add to DB failure
2023-07-12 19:52:02,473 - root - WARNING - ID 42568070
2023-07-12 19:52:02,473 - root - WARNING - ID mr_etelstan
2023-07-12 19:52:02,473 - root - WARNING - SQL add to DB failure
2023-07-12 19:53:30,751 - __main__ - WARNING - ID 42568070
2023-07-12 19:53:30,752 - __main__ - WARNING - ID mr_etelstan
2023-07-12 19:53:30,804 - __main__ - WARNING - User added
2023-07-12 17:22:33,795 - werkzeug - INFO - [31m[1mWARNING: This is a development server. Do not use it in a production deployment. Use a production WSGI server instead.[0m
 * Running on all addresses (0.0.0.0)
 * Running on http://127.0.0.1:80
 * Running on http://172.31.196.75:80
2023-07-12 17:22:33,795 - werkzeug - INFO - [33mPress CTRL+C to quit[0m
2023-07-12 17:22:35,891 - werkzeug - INFO - 172.31.196.1 - - [12/Jul/2023 17:22:35] "GET / HTTP/1.1" 200 -
2023-07-12 17:23:27,335 - werkzeug - INFO - [31m[1mWARNING: This is a development server. Do not use it in a production deployment. Use a production WSGI server instead.[0m
 * Running on all addresses (0.0.0.0)
 * Running on http://127.0.0.1:80
 * Running on http://172.31.196.75:80
2023-07-12 17:23:27,335 - werkzeug - INFO - [33mPress CTRL+C to quit[0m
2023-07-12 17:23:28,989 - werkzeug - INFO - 172.31.196.1 - - [12/Jul/2023 17:23:28] "[33mOPTIONS * HTTP/1.1[0m" 404 -
2023-07-12 17:23:29,070 - werkzeug - INFO - 172.31.196.1 - - [12/Jul/2023 17:23:29] "GET / HTTP/1.1" 200 -
2023-07-12 17:24:09,299 - root - WARNING - User added
2023-07-12 18:47:15,147 - root - WARNING - User 42568070 - mr_etelstan update
2023-07-13 14:02:04,445 - root - WARNING - User 42568070 - mr_etelstan update
2023-07-13 16:22:47,389 - root - WARNING - User 42568070 - mr_etelstan update
2023-07-13 18:43:48,063 - root - WARNING - User 42568070 - mr_etelstan update
2023-07-13 18:44:44,010 - root - WARNING - User 42568070 - mr_etelstan update
2023-07-13 18:46:31,758 - root - WARNING - User 42568070 - mr_etelstan update
2023-07-13 18:50:04,973 - root - WARNING - User 42568070 - mr_etelstan update
2023-07-13 18:50:05,021 - root - WARNING - User 42568070 - mr_etelstan update
2023-07-13 18:54:45,693 - root - WARNING - User 271764067 - None update
2023-07-13 19:21:45,233 - root - WARNING - User added
2023-07-13 19:22:48,506 - root - WARNING - User added
2023-07-13 19:25:23,204 - root - WARNING - User added
2023-07-13 19:28:22,797 - root - WARNING - User added
2023-07-13 19:37:08,917 - root - WARNING - User 42568070 - mr_etelstan update
2023-07-13 19:45:06,166 - root - WARNING - User 42568070 - mr_etelstan update
2023-07-13 19:45:16,360 - root - WARNING - User 42568070 - mr_etelstan update
2023-07-13 19:46:09,595 - root - WARNING - User added
2023-07-13 19:50:25,856 - root - WARNING - User 42568070 - mr_etelstan update
2023-07-13 19:52:07,053 - root - WARNING - User 271764067 - Empty update
2023-07-13 19:52:11,273 - root - WARNING - User 271764067 - Empty update
2023-07-13 19:52:21,482 - root - WARNING - User 271764067 - Empty update
2023-07-13 20:06:04,762 - root - WARNING - SQL add to DB failure - no such column: mr_etelstan
2023-07-13 20:08:11,308 - root - WARNING - SQL add to DB failure - no such column: mr_etelstan
2023-07-13 20:09:46,949 - root - WARNING - User 42568070 - mr_etelstan update
2023-07-13 20:14:02,986 - root - WARNING - User 42568070 - mr_etelstan update
2023-07-14 03:48:34,120 - root - WARNING - User 42568070 - mr_etelstan update
2023-07-14 04:11:46,887 - root - WARNING - User 42568070 - mr_etelstan update
2023-07-14 04:19:31,881 - root - WARNING - User 42568070 - mr_etelstan update
2023-07-14 04:19:36,549 - root - WARNING - User 42568070 - mr_etelstan update
2023-07-14 04:20:08,375 - root - WARNING - User 42568070 - mr_etelstan update
